File is already open in
D:\py3.11\python.exe (PID 37324)
PS E:\Download\FaceSimilarityEngine (1)\FaceSimilarityEngine> python app.py
Applied providers: ['CPUExecutionProvider'], with options: {'CPUExecutionProvider': {}}
model ignore: C:\Users\gamer/.insightface\models\buffalo_l\1k3d68.onnx landmark_3d_68
Applied providers: ['CPUExecutionProvider'], with options: {'CPUExecutionProvider': {}}
model ignore: C:\Users\gamer/.insightface\models\buffalo_l\2d106det.onnx landmark_2d_106
Applied providers: ['CPUExecutionProvider'], with options: {'CPUExecutionProvider': {}}
find model: C:\Users\gamer/.insightface\models\buffalo_l\det_10g.onnx detection [1, 3, '?', '?'] 127.5 128.0
Applied providers: ['CPUExecutionProvider'], with options: {'CPUExecutionProvider': {}}
model ignore: C:\Users\gamer/.insightface\models\buffalo_l\genderage.onnx genderage
Applied providers: ['CPUExecutionProvider'], with options: {'CPUExecutionProvider': {}}
find model: C:\Users\gamer/.insightface\models\buffalo_l\w600k_r50.onnx recognition ['None', 3, 112, 112] 127.5 127.5
ERROR:root:Failed to initialize InsightFace models: 'InsightFaceEngine' object has no attribute 'detection_size'
INFO:root:Falling back to basic face detection
INFO:root:Fallback OpenCV detector loaded
INFO:root:InsightFaceEngine initialized
INFO:root:No existing FAISS index found, starting fresh
INFO:root:FAISS index initialized with 0 vectors
INFO:root:FAISS search engine initialized with 512D embeddings
INFO:root:Database tables and indices created successfully
INFO:root:Database connection established and tables created
INFO:root:Database manager initialized with data/face_search.db
INFO:WDM:====== WebDriver manager ======
INFO:WDM:Get LATEST chromedriver version for google-chrome
DEBUG:urllib3.connectionpool:Starting new HTTPS connection (1): googlechromelabs.github.io:443
DEBUG:urllib3.connectionpool:https://googlechromelabs.github.io:443 "GET /chrome-for-testing/latest-patch-versions-per-build.json HTTP/1.1" 200 11787
INFO:WDM:Get LATEST chromedriver version for google-chrome
DEBUG:urllib3.connectionpool:Starting new HTTPS connection (1): googlechromelabs.github.io:443
DEBUG:urllib3.connectionpool:https://googlechromelabs.github.io:443 "GET /chrome-for-testing/latest-patch-versions-per-build.json HTTP/1.1" 200 11787
INFO:WDM:Driver [C:\Users\gamer\.wdm\drivers\chromedriver\win64\137.0.7151.119\chromedriver-win32/chromedriver.exe] found in cache
DEBUG:selenium.webdriver.common.driver_finder:Skipping Selenium Manager; path to chrome driver specified in Service class: C:\Users\gamer\.wdm\drivers\chromedriver\win64\137.0.7151.119\chromedriver-win32/chromedriver.exe
DEBUG:selenium.webdriver.common.service:Started executable: `C:\Users\gamer\.wdm\drivers\chromedriver\win64\137.0.7151.119\chromedriver-win32/chromedriver.exe` in a child process with pid: 32368 using 0 to output -3
DEBUG:selenium.webdriver.remote.remote_connection:POST http://localhost:56830/session {'capabilities': {'firstMatch': [{}], 'alwaysMatch': {'browserName': 'chrome', 'pageLoadStrategy': <PageLoadStrategy.normal: 'normal'>, 'goog:chromeOptions': {'extensions': [], 'args': ['--headless', '--no-sandbox', '--disable-dev-shm-usage', '--disable-gpu', '--window-size=1920,1080', '--user-agent=Mozilla/5.0 (Windows NT 10.0; Win64; x64) AppleWebKit/537.36']}}}}
DEBUG:urllib3.connectionpool:Starting new HTTP connection (1): localhost:56830

DevTools listening on ws://127.0.0.1:56835/devtools/browser/4339bb80-4fba-4cb9-a047-4bfac71f5908
DEBUG:urllib3.connectionpool:http://localhost:56830 "POST /session HTTP/1.1" 200 0
DEBUG:selenium.webdriver.remote.remote_connection:Remote response: status=200 | data={"value":{"capabilities":{"acceptInsecureCerts":false,"browserName":"chrome","browserVersion":"137.0.7151.120","chrome":{"chromedriverVersion":"137.0.7151.119 (e0ac9d12dff5f2d33c935958b06bf1ded7f1c08c-refs/branch-heads/7151@{#2356})","userDataDir":"C:\\Users\\gamer\\AppData\\Local\\Temp\\scoped_dir32368_1384903361"},"fedcm:accounts":true,"goog:chromeOptions":{"debuggerAddress":"localhost:56835"},"networkConnectionEnabled":false,"pageLoadStrategy":"normal","platformName":"windows","proxy":{},"setWindowRect":true,"strictFileInteractability":false,"timeouts":{"implicit":0,"pageLoad":300000,"script":30000},"unhandledPromptBehavior":"dismiss and notify","webauthn:extension:credBlob":true,"webauthn:extension:largeBlob":true,"webauthn:extension:minPinLength":true,"webauthn:extension:prf":true,"webauthn:virtualAuthenticators":true},"sessionId":"6112d3fae2b9aab9ef967f59e2b0234d"}} | headers=HTTPHeaderDict({'Content-Length': '884', 'Content-Type': 'application/json; charset=utf-8', 'cache-control': 'no-cache'})
DEBUG:selenium.webdriver.remote.remote_connection:Finished Request
INFO:root:Selenium webdriver initialized
INFO:root:WebCrawler initialized successfully
INFO:root:ImageProcessor initialized
 * Serving Flask app 'app'
 * Debug mode: on
INFO:werkzeug:WARNING: This is a development server. Do not use it in a production deployment. Use a production WSGI server instead.
 * Running on all addresses (0.0.0.0)
 * Running on http://127.0.0.1:5000
 * Running on http://192.168.1.101:5000
INFO:werkzeug:Press CTRL+C to quit
INFO:werkzeug: * Restarting with watchdog (windowsapi)
Applied providers: ['CPUExecutionProvider'], with options: {'CPUExecutionProvider': {}}
model ignore: C:\Users\gamer/.insightface\models\buffalo_l\1k3d68.onnx landmark_3d_68
Applied providers: ['CPUExecutionProvider'], with options: {'CPUExecutionProvider': {}}
model ignore: C:\Users\gamer/.insightface\models\buffalo_l\2d106det.onnx landmark_2d_106
Applied providers: ['CPUExecutionProvider'], with options: {'CPUExecutionProvider': {}}
find model: C:\Users\gamer/.insightface\models\buffalo_l\det_10g.onnx detection [1, 3, '?', '?'] 127.5 128.0
Applied providers: ['CPUExecutionProvider'], with options: {'CPUExecutionProvider': {}}
model ignore: C:\Users\gamer/.insightface\models\buffalo_l\genderage.onnx genderage
WARNING: All log messages before absl::InitializeLog() is called are written to STDERR
I0000 00:00:1750952411.120147   27548 voice_transcription.cc:58] Registering VoiceTranscriptionCapability
Applied providers: ['CPUExecutionProvider'], with options: {'CPUExecutionProvider': {}}
find model: C:\Users\gamer/.insightface\models\buffalo_l\w600k_r50.onnx recognition ['None', 3, 112, 112] 127.5 127.5
ERROR:root:Failed to initialize InsightFace models: 'InsightFaceEngine' object has no attribute 'detection_size'
INFO:root:Falling back to basic face detection
INFO:root:Fallback OpenCV detector loaded
INFO:root:InsightFaceEngine initialized
INFO:root:No existing FAISS index found, starting fresh
INFO:root:FAISS index initialized with 0 vectors
INFO:root:FAISS search engine initialized with 512D embeddings
ERROR:root:Error initializing database: IO Error: Cannot open file "e:\download\facesimilarityengine (1)\facesimilarityengine\data\face_search.db": Der Prozess kann nicht auf die Datei zugreifen, da sie von einem anderen Prozess verwendet wird.

File is already open in
D:\py3.11\python.exe (PID 46404)
Traceback (most recent call last):
  File "E:\Download\FaceSimilarityEngine (1)\FaceSimilarityEngine\app.py", line 39, in <module>
    db_manager = DatabaseManager()
                 ^^^^^^^^^^^^^^^^^
  File "E:\Download\FaceSimilarityEngine (1)\FaceSimilarityEngine\database_manager.py", line 26, in __init__
    self.initialize_database()
  File "E:\Download\FaceSimilarityEngine (1)\FaceSimilarityEngine\database_manager.py", line 33, in initialize_database
    self.conn = duckdb.connect(self.db_path)
                ^^^^^^^^^^^^^^^^^^^^^^^^^^^^
duckdb.duckdb.IOException: IO Error: Cannot open file "e:\download\facesimilarityengine (1)\facesimilarityengine\data\face_search.db": Der Prozess kann nicht auf die Datei zugreifen, da sie von einem anderen Prozess verwendet wird.

File is already open in
D:\py3.11\python.exe (PID 46404)
PS E:\Download\FaceSimilarityEngine (1)\FaceSimilarityEngine>